outputs/trades_VolatilityAdjusted_BuyPressure.csv
timestamp,strategy,regime,price,quantity,mm_bought,mm_sold
1,VolatilityAdjusted,BuyPressure,100.050000,15,0,0
2,VolatilityAdjusted,BuyPressure,100.050000,5,0,0
6,VolatilityAdjusted,BuyPressure,99.950000,15,0,0
7,VolatilityAdjusted,BuyPressure,99.950000,1,0,0
9,VolatilityAdjusted,BuyPressure,100.050000,18,0,0
10,VolatilityAdjusted,BuyPressure,100.050000,12,0,0
10,VolatilityAdjusted,BuyPressure,100.100000,2,0,0
11,VolatilityAdjusted,BuyPressure,100.088465,10,0,1
11,VolatilityAdjusted,BuyPressure,100.100000,1,0,0
12,VolatilityAdjusted,BuyPressure,100.100000,11,0,0
14,VolatilityAdjusted,BuyPressure,100.100000,5,0,0
15,VolatilityAdjusted,BuyPressure,99.976090,10,1,0
16,VolatilityAdjusted,BuyPressure,99.950000,8,0,0
19,VolatilityAdjusted,BuyPressure,100.100000,11,0,0
20,VolatilityAdjusted,BuyPressure,100.100000,17,0,0
21,VolatilityAdjusted,BuyPressure,100.100000,3,0,0
21,VolatilityAdjusted,BuyPressure,100.112316,10,0,1
21,VolatilityAdjusted,BuyPressure,100.150000,4,0,0
23,VolatilityAdjusted,BuyPressure,100.150000,6,0,0
24,VolatilityAdjusted,BuyPressure,100.150000,6,0,0
26,VolatilityAdjusted,BuyPressure,100.012251,2,0,0
26,VolatilityAdjusted,BuyPressure,99.993063,7,1,0
27,VolatilityAdjusted,BuyPressure,100.150000,8,0,0
28,VolatilityAdjusted,BuyPressure,100.150000,14,0,0
30,VolatilityAdjusted,BuyPressure,100.150000,12,0,0
30,VolatilityAdjusted,BuyPressure,100.200000,4,0,0
31,VolatilityAdjusted,BuyPressure,100.192074,10,0,1
31,VolatilityAdjusted,BuyPressure,100.200000,4,0,0
33,VolatilityAdjusted,BuyPressure,100.200000,6,0,0
35,VolatilityAdjusted,BuyPressure,100.200000,15,0,0
38,VolatilityAdjusted,BuyPressure,100.126955,3,0,0
41,VolatilityAdjusted,BuyPressure,100.200000,1,0,0
42,VolatilityAdjusted,BuyPressure,100.200000,2,0,0
44,VolatilityAdjusted,BuyPressure,100.200000,13,0,0
46,VolatilityAdjusted,BuyPressure,100.200000,5,0,0
46,VolatilityAdjusted,BuyPressure,100.206464,1,0,0
46,VolatilityAdjusted,BuyPressure,100.219673,10,0,1
46,VolatilityAdjusted,BuyPressure,100.250000,1,0,0
49,VolatilityAdjusted,BuyPressure,100.235327,1,0,0
54,VolatilityAdjusted,BuyPressure,100.235327,5,0,0
58,VolatilityAdjusted,BuyPressure,100.235327,10,0,0
61,VolatilityAdjusted,BuyPressure,100.235327,3,0,0
61,VolatilityAdjusted,BuyPressure,100.250000,1,0,0
62,VolatilityAdjusted,BuyPressure,100.250000,14,0,0
63,VolatilityAdjusted,BuyPressure,100.250000,3,0,0
64,VolatilityAdjusted,BuyPressure,100.250000,5,0,0
66,VolatilityAdjusted,BuyPressure,100.250000,10,0,0
67,VolatilityAdjusted,BuyPressure,100.250000,16,0,0
67,VolatilityAdjusted,BuyPressure,100.272083,4,0,1
68,VolatilityAdjusted,BuyPressure,100.272083,6,0,1
68,VolatilityAdjusted,BuyPressure,100.277322,1,0,0
68,VolatilityAdjusted,BuyPressure,100.300000,6,0,0
69,VolatilityAdjusted,BuyPressure,100.241325,6,0,0
71,VolatilityAdjusted,BuyPressure,100.249624,10,1,0
71,VolatilityAdjusted,BuyPressure,100.241325,2,0,0
71,VolatilityAdjusted,BuyPressure,100.199701,6,0,0
72,VolatilityAdjusted,BuyPressure,100.300000,1,0,0
73,VolatilityAdjusted,BuyPressure,100.199701,7,0,0
74,VolatilityAdjusted,BuyPressure,100.199701,5,0,0
74,VolatilityAdjusted,BuyPressure,100.194464,2,0,0
74,VolatilityAdjusted,BuyPressure,100.193057,1,0,0
75,VolatilityAdjusted,BuyPressure,100.300000,7,0,0
76,VolatilityAdjusted,BuyPressure,100.300000,15,0,0
79,VolatilityAdjusted,BuyPressure,100.300000,11,0,0
81,VolatilityAdjusted,BuyPressure,100.256965,7,1,0
82,VolatilityAdjusted,BuyPressure,100.300000,4,0,0
85,VolatilityAdjusted,BuyPressure,100.300000,6,0,0
85,VolatilityAdjusted,BuyPressure,100.303095,2,0,1
86,VolatilityAdjusted,BuyPressure,100.303095,8,0,1
86,VolatilityAdjusted,BuyPressure,100.333838,8,0,0
89,VolatilityAdjusted,BuyPressure,100.333838,2,0,0
89,VolatilityAdjusted,BuyPressure,100.350000,13,0,0
91,VolatilityAdjusted,BuyPressure,100.312963,2,0,0
92,VolatilityAdjusted,BuyPressure,100.350000,13,0,0
93,VolatilityAdjusted,BuyPressure,100.350000,14,0,0
95,VolatilityAdjusted,BuyPressure,100.350000,10,0,0
95,VolatilityAdjusted,BuyPressure,100.373513,9,0,1
97,VolatilityAdjusted,BuyPressure,100.373513,1,0,1
97,VolatilityAdjusted,BuyPressure,100.381867,10,0,1
97,VolatilityAdjusted,BuyPressure,100.400000,8,0,0
102,VolatilityAdjusted,BuyPressure,100.400000,13,0,0
103,VolatilityAdjusted,BuyPressure,100.337617,1,1,0
104,VolatilityAdjusted,BuyPressure,100.337617,9,1,0
104,VolatilityAdjusted,BuyPressure,100.335068,7,0,0
105,VolatilityAdjusted,BuyPressure,100.400000,5,0,0
106,VolatilityAdjusted,BuyPressure,100.335068,6,0,0
106,VolatilityAdjusted,BuyPressure,100.312963,4,0,0
107,VolatilityAdjusted,BuyPressure,100.400000,4,0,0
109,VolatilityAdjusted,BuyPressure,100.312963,4,0,0
110,VolatilityAdjusted,BuyPressure,100.300915,10,1,0
110,VolatilityAdjusted,BuyPressure,100.287109,10,0,0
111,VolatilityAdjusted,BuyPressure,100.319227,9,1,0
112,VolatilityAdjusted,BuyPressure,100.319227,1,1,0
112,VolatilityAdjusted,BuyPressure,100.287109,2,0,0
114,VolatilityAdjusted,BuyPressure,100.287109,5,0,0
114,VolatilityAdjusted,BuyPressure,100.281894,3,0,0
115,VolatilityAdjusted,BuyPressure,100.400000,20,0,0
116,VolatilityAdjusted,BuyPressure,100.425186,5,0,1
118,VolatilityAdjusted,BuyPressure,100.425186,4,0,1
119,VolatilityAdjusted,BuyPressure,100.425186,1,0,1
119,VolatilityAdjusted,BuyPressure,100.445161,1,0,1
121,VolatilityAdjusted,BuyPressure,100.445161,9,0,1
121,VolatilityAdjusted,BuyPressure,100.450000,6,0,0
122,VolatilityAdjusted,BuyPressure,100.450000,5,0,0
123,VolatilityAdjusted,BuyPressure,100.450000,6,0,0
124,VolatilityAdjusted,BuyPressure,100.357467,3,0,0
124,VolatilityAdjusted,BuyPressure,100.333060,10,1,0
124,VolatilityAdjusted,BuyPressure,100.274614,3,0,0
124,VolatilityAdjusted,BuyPressure,100.256965,1,1,0
125,VolatilityAdjusted,BuyPressure,100.256965,2,1,0
125,VolatilityAdjusted,BuyPressure,100.245286,6,0,0
125,VolatilityAdjusted,BuyPressure,100.235485,3,0,0
127,VolatilityAdjusted,BuyPressure,100.450000,15,0,0
128,VolatilityAdjusted,BuyPressure,100.450000,3,0,0
129,VolatilityAdjusted,BuyPressure,100.348004,9,0,0
131,VolatilityAdjusted,BuyPressure,100.450000,15,0,0
131,VolatilityAdjusted,BuyPressure,100.451573,2,0,0
132,VolatilityAdjusted,BuyPressure,100.451573,17,0,0
132,VolatilityAdjusted,BuyPressure,100.453844,2,0,0
135,VolatilityAdjusted,BuyPressure,100.356695,7,1,0
136,VolatilityAdjusted,BuyPressure,100.356695,3,1,0
136,VolatilityAdjusted,BuyPressure,100.348004,1,0,0
138,VolatilityAdjusted,BuyPressure,100.348004,1,0,0
138,VolatilityAdjusted,BuyPressure,100.342806,19,0,0
143,VolatilityAdjusted,BuyPressure,100.453844,1,0,0
143,VolatilityAdjusted,BuyPressure,100.459719,10,0,1
143,VolatilityAdjusted,BuyPressure,100.459764,6,0,1
144,VolatilityAdjusted,BuyPressure,100.378956,8,0,0
144,VolatilityAdjusted,BuyPressure,100.372124,4,0,0
146,VolatilityAdjusted,BuyPressure,100.372124,11,0,0
148,VolatilityAdjusted,BuyPressure,100.459764,4,0,1
148,VolatilityAdjusted,BuyPressure,100.468447,1,0,1
149,VolatilityAdjusted,BuyPressure,100.343942,5,1,0
154,VolatilityAdjusted,BuyPressure,100.371261,6,0,0
154,VolatilityAdjusted,BuyPressure,100.343942,1,1,0
157,VolatilityAdjusted,BuyPressure,100.457982,8,0,1
159,VolatilityAdjusted,BuyPressure,100.457982,2,0,1
164,VolatilityAdjusted,BuyPressure,100.399750,8,0,0
166,VolatilityAdjusted,BuyPressure,100.450252,15,0,0
166,VolatilityAdjusted,BuyPressure,100.468447,2,0,1
167,VolatilityAdjusted,BuyPressure,100.353782,10,1,0
167,VolatilityAdjusted,BuyPressure,100.343942,3,1,0
168,VolatilityAdjusted,BuyPressure,100.343942,1,1,0
168,VolatilityAdjusted,BuyPressure,100.341945,12,0,0
168,VolatilityAdjusted,BuyPressure,100.335285,7,1,0
169,VolatilityAdjusted,BuyPressure,100.335285,3,1,0
169,VolatilityAdjusted,BuyPressure,100.333163,3,0,0
171,VolatilityAdjusted,BuyPressure,100.333163,6,0,0
171,VolatilityAdjusted,BuyPressure,100.328975,7,0,0
172,VolatilityAdjusted,BuyPressure,100.428601,10,0,1
172,VolatilityAdjusted,BuyPressure,100.468447,4,0,1
175,VolatilityAdjusted,BuyPressure,100.468447,3,0,1
175,VolatilityAdjusted,BuyPressure,100.472405,8,0,1
177,VolatilityAdjusted,BuyPressure,100.472405,2,0,1
