outputs/trades_VolatilityAdjusted_SellPressure.csv
timestamp,strategy,regime,price,quantity,mm_bought,mm_sold
3,VolatilityAdjusted,SellPressure,99.975621,2,0,0
3,VolatilityAdjusted,SellPressure,99.950000,18,0,0
4,VolatilityAdjusted,SellPressure,99.950000,9,0,0
7,VolatilityAdjusted,SellPressure,99.950000,15,0,0
9,VolatilityAdjusted,SellPressure,99.950000,8,0,0
9,VolatilityAdjusted,SellPressure,99.915751,2,0,0
10,VolatilityAdjusted,SellPressure,100.050000,7,0,0
12,VolatilityAdjusted,SellPressure,100.020836,10,0,1
12,VolatilityAdjusted,SellPressure,100.050000,10,0,0
13,VolatilityAdjusted,SellPressure,99.915751,12,0,0
16,VolatilityAdjusted,SellPressure,100.050000,10,0,0
17,VolatilityAdjusted,SellPressure,100.050000,18,0,0
19,VolatilityAdjusted,SellPressure,100.050000,1,0,0
20,VolatilityAdjusted,SellPressure,99.912233,10,1,0
20,VolatilityAdjusted,SellPressure,99.902984,8,0,0
21,VolatilityAdjusted,SellPressure,100.036996,10,0,1
21,VolatilityAdjusted,SellPressure,100.050000,3,0,0
25,VolatilityAdjusted,SellPressure,100.050000,1,0,0
25,VolatilityAdjusted,SellPressure,100.050324,6,0,0
25,VolatilityAdjusted,SellPressure,100.062413,3,0,0
25,VolatilityAdjusted,SellPressure,100.100000,10,0,0
26,VolatilityAdjusted,SellPressure,99.953614,11,0,0
27,VolatilityAdjusted,SellPressure,99.953614,4,0,0
30,VolatilityAdjusted,SellPressure,100.099833,5,0,0
30,VolatilityAdjusted,SellPressure,100.100000,13,0,0
32,VolatilityAdjusted,SellPressure,100.048655,10,0,1
32,VolatilityAdjusted,SellPressure,100.100000,3,0,0
33,VolatilityAdjusted,SellPressure,99.930883,6,0,0
33,VolatilityAdjusted,SellPressure,99.929085,2,1,0
34,VolatilityAdjusted,SellPressure,100.100000,12,0,0
35,VolatilityAdjusted,SellPressure,100.100000,12,0,0
35,VolatilityAdjusted,SellPressure,100.106890,3,0,0
36,VolatilityAdjusted,SellPressure,99.929085,8,1,0
36,VolatilityAdjusted,SellPressure,99.928823,4,0,0
38,VolatilityAdjusted,SellPressure,99.928823,12,0,0
38,VolatilityAdjusted,SellPressure,99.919977,8,1,0
39,VolatilityAdjusted,SellPressure,99.919977,2,1,0
39,VolatilityAdjusted,SellPressure,99.902984,2,0,0
40,VolatilityAdjusted,SellPressure,100.106890,9,0,0
40,VolatilityAdjusted,SellPressure,100.150000,10,0,0
41,VolatilityAdjusted,SellPressure,100.073802,10,0,1
41,VolatilityAdjusted,SellPressure,100.150000,6,0,0
42,VolatilityAdjusted,SellPressure,99.949426,10,1,0
42,VolatilityAdjusted,SellPressure,99.902984,7,0,0
42,VolatilityAdjusted,SellPressure,99.900000,1,0,0
43,VolatilityAdjusted,SellPressure,100.150000,5,0,0
44,VolatilityAdjusted,SellPressure,100.150000,10,0,0
45,VolatilityAdjusted,SellPressure,100.150000,17,0,0
48,VolatilityAdjusted,SellPressure,99.901022,11,0,0
48,VolatilityAdjusted,SellPressure,99.900000,6,0,0
49,VolatilityAdjusted,SellPressure,100.150000,2,0,0
49,VolatilityAdjusted,SellPressure,100.162733,10,0,0
50,VolatilityAdjusted,SellPressure,99.900000,9,0,0
51,VolatilityAdjusted,SellPressure,100.105503,10,0,1
51,VolatilityAdjusted,SellPressure,100.162733,3,0,0
51,VolatilityAdjusted,SellPressure,100.163661,7,0,0
58,VolatilityAdjusted,SellPressure,100.073279,2,0,0
58,VolatilityAdjusted,SellPressure,100.141158,12,0,0
58,VolatilityAdjusted,SellPressure,100.146234,1,0,0
62,VolatilityAdjusted,SellPressure,100.029752,7,0,0
62,VolatilityAdjusted,SellPressure,100.003113,10,1,0
62,VolatilityAdjusted,SellPressure,99.990939,2,0,0
66,VolatilityAdjusted,SellPressure,100.118610,13,0,0
66,VolatilityAdjusted,SellPressure,100.123623,1,0,1
71,VolatilityAdjusted,SellPressure,100.111931,10,0,1
71,VolatilityAdjusted,SellPressure,100.123623,8,0,1
72,VolatilityAdjusted,SellPressure,100.123623,1,0,1
72,VolatilityAdjusted,SellPressure,100.146234,5,0,0
73,VolatilityAdjusted,SellPressure,100.146234,5,0,0
75,VolatilityAdjusted,SellPressure,100.050372,11,0,0
77,VolatilityAdjusted,SellPressure,100.050372,8,0,0
77,VolatilityAdjusted,SellPressure,100.035538,7,0,0
78,VolatilityAdjusted,SellPressure,100.035538,6,0,0
78,VolatilityAdjusted,SellPressure,100.029737,6,0,0
79,VolatilityAdjusted,SellPressure,100.146234,7,0,0
79,VolatilityAdjusted,SellPressure,100.163661,3,0,0
79,VolatilityAdjusted,SellPressure,100.164862,3,0,0
79,VolatilityAdjusted,SellPressure,100.179640,1,0,0
81,VolatilityAdjusted,SellPressure,100.029737,2,0,0
82,VolatilityAdjusted,SellPressure,100.029737,6,0,0
82,VolatilityAdjusted,SellPressure,100.003043,4,0,0
85,VolatilityAdjusted,SellPressure,100.003043,10,0,0
86,VolatilityAdjusted,SellPressure,100.003043,2,0,0
87,VolatilityAdjusted,SellPressure,100.003043,3,0,0
87,VolatilityAdjusted,SellPressure,99.996791,10,1,0
87,VolatilityAdjusted,SellPressure,99.994428,1,1,0
88,VolatilityAdjusted,SellPressure,99.994428,6,1,0
91,VolatilityAdjusted,SellPressure,99.999155,3,0,0
93,VolatilityAdjusted,SellPressure,99.994428,3,1,0
93,VolatilityAdjusted,SellPressure,99.990939,6,0,0
93,VolatilityAdjusted,SellPressure,99.987233,2,0,0
93,VolatilityAdjusted,SellPressure,99.977651,9,1,0
94,VolatilityAdjusted,SellPressure,99.999155,3,0,0
94,VolatilityAdjusted,SellPressure,100.044736,3,0,1
95,VolatilityAdjusted,SellPressure,100.044736,7,0,1
95,VolatilityAdjusted,SellPressure,100.084888,4,0,0
96,VolatilityAdjusted,SellPressure,99.977651,1,1,0
96,VolatilityAdjusted,SellPressure,99.970313,1,0,0
96,VolatilityAdjusted,SellPressure,99.947393,9,0,0
96,VolatilityAdjusted,SellPressure,99.919877,2,1,0
97,VolatilityAdjusted,SellPressure,100.084888,3,0,0
98,VolatilityAdjusted,SellPressure,99.919877,2,1,0
99,VolatilityAdjusted,SellPressure,100.084888,5,0,0
99,VolatilityAdjusted,SellPressure,100.095359,9,0,0
99,VolatilityAdjusted,SellPressure,100.119872,2,0,1
100,VolatilityAdjusted,SellPressure,99.919877,6,1,0
100,VolatilityAdjusted,SellPressure,99.900000,9,0,0
101,VolatilityAdjusted,SellPressure,100.064015,10,0,1
101,VolatilityAdjusted,SellPressure,100.119872,8,0,1
103,VolatilityAdjusted,SellPressure,99.935112,10,1,0
105,VolatilityAdjusted,SellPressure,99.900000,13,0,0
106,VolatilityAdjusted,SellPressure,100.129930,3,0,0
106,VolatilityAdjusted,SellPressure,100.169774,9,0,0
107,VolatilityAdjusted,SellPressure,99.900000,12,0,0
107,VolatilityAdjusted,SellPressure,99.878207,5,0,0
109,VolatilityAdjusted,SellPressure,99.878207,1,0,0
109,VolatilityAdjusted,SellPressure,99.856053,10,0,0
110,VolatilityAdjusted,SellPressure,99.856053,4,0,0
110,VolatilityAdjusted,SellPressure,99.850000,7,0,0
115,VolatilityAdjusted,SellPressure,100.030464,8,0,1
116,VolatilityAdjusted,SellPressure,100.030464,1,0,1
117,VolatilityAdjusted,SellPressure,99.904043,10,1,0
117,VolatilityAdjusted,SellPressure,99.850000,4,0,0
118,VolatilityAdjusted,SellPressure,99.850000,13,0,0
119,VolatilityAdjusted,SellPressure,100.030464,1,0,1
119,VolatilityAdjusted,SellPressure,100.049191,12,0,0
120,VolatilityAdjusted,SellPressure,99.850000,17,0,0
121,VolatilityAdjusted,SellPressure,100.029574,10,0,1
121,VolatilityAdjusted,SellPressure,100.060328,1,0,0
121,VolatilityAdjusted,SellPressure,100.169774,6,0,0
123,VolatilityAdjusted,SellPressure,99.902177,10,1,0
123,VolatilityAdjusted,SellPressure,99.850000,1,0,0
124,VolatilityAdjusted,SellPressure,100.020814,6,0,0
127,VolatilityAdjusted,SellPressure,99.850000,8,0,0
127,VolatilityAdjusted,SellPressure,99.848561,6,0,0
128,VolatilityAdjusted,SellPressure,99.848561,11,0,0
129,VolatilityAdjusted,SellPressure,99.839217,15,0,0
129,VolatilityAdjusted,SellPressure,99.826173,1,0,0
130,VolatilityAdjusted,SellPressure,100.001942,1,0,0
132,VolatilityAdjusted,SellPressure,99.888161,3,1,0
133,VolatilityAdjusted,SellPressure,99.888161,2,1,0
134,VolatilityAdjusted,SellPressure,99.888161,5,1,0
134,VolatilityAdjusted,SellPressure,99.826173,2,0,0
135,VolatilityAdjusted,SellPressure,99.826173,13,0,0
136,VolatilityAdjusted,SellPressure,100.001942,7,0,0
136,VolatilityAdjusted,SellPressure,100.016267,3,0,1
137,VolatilityAdjusted,SellPressure,99.826173,2,0,0
137,VolatilityAdjusted,SellPressure,99.800000,14,0,0
138,VolatilityAdjusted,SellPressure,99.800000,8,0,0
140,VolatilityAdjusted,SellPressure,100.016267,6,0,1
141,VolatilityAdjusted,SellPressure,99.971273,6,0,1
143,VolatilityAdjusted,SellPressure,99.843072,6,1,0
145,VolatilityAdjusted,SellPressure,99.843072,4,1,0
